(dp1
S'output'
p2
S'<type \'exceptions.RuntimeError\'> Failure to connect, tried 5 times:\nTraceback (most recent call last):\n  File "C:\\cygwin64\\home\\austi\\web2py\\gluon\\packages\\dal\\pydal\\base.py", line 455, in __init__\n    self._adapter = adapter(**kwargs)\n  File "C:\\cygwin64\\home\\austi\\web2py\\gluon\\packages\\dal\\pydal\\adapters\\__init__.py", line 40, in __call__\n    obj = super(AdapterMeta, cls).__call__(*args, **kwargs)\n  File "C:\\cygwin64\\home\\austi\\web2py\\gluon\\packages\\dal\\pydal\\adapters\\base.py", line 369, in __init__\n    super(SQLAdapter, self).__init__(*args, **kwargs)\n  File "C:\\cygwin64\\home\\austi\\web2py\\gluon\\packages\\dal\\pydal\\adapters\\base.py", line 53, in __init__\n    self.reconnect()\n  File "C:\\cygwin64\\home\\austi\\web2py\\gluon\\packages\\dal\\pydal\\connection.py", line 152, in reconnect\n    self.connection = self.connector()\n  File "C:\\cygwin64\\home\\austi\\web2py\\gluon\\packages\\dal\\pydal\\adapters\\mysql.py", line 52, in connector\n    return self.driver.connect(**self.driver_args)\n  File "C:\\cygwin64\\home\\austi\\web2py\\gluon\\contrib\\pymysql\\__init__.py", line 90, in Connect\n    return Connection(*args, **kwargs)\n  File "C:\\cygwin64\\home\\austi\\web2py\\gluon\\contrib\\pymysql\\connections.py", line 688, in __init__\n    self.connect()\n  File "C:\\cygwin64\\home\\austi\\web2py\\gluon\\contrib\\pymysql\\connections.py", line 937, in connect\n    raise exc\nOperationalError: (2003, "Can\'t connect to MySQL server on \'squish.mysql.pythonanywhere-services.com\' ([Errno 10060] A connection attempt failed because the connected party did not properly respond after a period of time, or established connection failed because connected host has failed to respond)")\n'
p3
sS'layer'
p4
S'C:\\cygwin64\\home\\austi\\web2py\\applications\\Squish\\models\\db.py'
p5
sS'code'
p6
S'<code object <module> at 0B535EC0, file "C:\\cygwin64\\home\\austi\\web2py\\applications\\Squish\\models\\db.py", line 7>'
p7
sS'snapshot'
p8
(dp9
sS'traceback'
p10
S'Traceback (most recent call last):\n  File "C:\\cygwin64\\home\\austi\\web2py\\gluon\\restricted.py", line 219, in restricted\n    exec(ccode, environment)\n  File "C:\\cygwin64\\home\\austi\\web2py\\applications\\Squish\\models\\db.py", line 33, in <module>\n    db = DAL(\'mysql://squish:squishpassword@squish.mysql.pythonanywhere-services.com/squish$default?set_encoding=utf8mb4\')\n  File "C:\\cygwin64\\home\\austi\\web2py\\gluon\\packages\\dal\\pydal\\base.py", line 170, in __call__\n    obj = super(MetaDAL, cls).__call__(*args, **kwargs)\n  File "C:\\cygwin64\\home\\austi\\web2py\\gluon\\packages\\dal\\pydal\\base.py", line 475, in __init__\n    "Failure to connect, tried %d times:\\n%s" % (attempts, tb)\nRuntimeError: Failure to connect, tried 5 times:\nTraceback (most recent call last):\n  File "C:\\cygwin64\\home\\austi\\web2py\\gluon\\packages\\dal\\pydal\\base.py", line 455, in __init__\n    self._adapter = adapter(**kwargs)\n  File "C:\\cygwin64\\home\\austi\\web2py\\gluon\\packages\\dal\\pydal\\adapters\\__init__.py", line 40, in __call__\n    obj = super(AdapterMeta, cls).__call__(*args, **kwargs)\n  File "C:\\cygwin64\\home\\austi\\web2py\\gluon\\packages\\dal\\pydal\\adapters\\base.py", line 369, in __init__\n    super(SQLAdapter, self).__init__(*args, **kwargs)\n  File "C:\\cygwin64\\home\\austi\\web2py\\gluon\\packages\\dal\\pydal\\adapters\\base.py", line 53, in __init__\n    self.reconnect()\n  File "C:\\cygwin64\\home\\austi\\web2py\\gluon\\packages\\dal\\pydal\\connection.py", line 152, in reconnect\n    self.connection = self.connector()\n  File "C:\\cygwin64\\home\\austi\\web2py\\gluon\\packages\\dal\\pydal\\adapters\\mysql.py", line 52, in connector\n    return self.driver.connect(**self.driver_args)\n  File "C:\\cygwin64\\home\\austi\\web2py\\gluon\\contrib\\pymysql\\__init__.py", line 90, in Connect\n    return Connection(*args, **kwargs)\n  File "C:\\cygwin64\\home\\austi\\web2py\\gluon\\contrib\\pymysql\\connections.py", line 688, in __init__\n    self.connect()\n  File "C:\\cygwin64\\home\\austi\\web2py\\gluon\\contrib\\pymysql\\connections.py", line 937, in connect\n    raise exc\nOperationalError: (2003, "Can\'t connect to MySQL server on \'squish.mysql.pythonanywhere-services.com\' ([Errno 10060] A connection attempt failed because the connected party did not properly respond after a period of time, or established connection failed because connected host has failed to respond)")\n\n'
p11
s.